Traceback (most recent call last):
  File "C:\Users\marco\Alquimista\0-InTheOven\agentes_u\venv\lib\site-packages\botasaurus\request_decorator.py", line 108, in run_task
    result = func(reqs, data, metadata)
  File "C:\Users\marco\Alquimista\0-InTheOven\agentes_u\agente_leads\main.py", line 35, in scrape_place_info
    title = extract_title(html)
  File "C:\Users\marco\Alquimista\0-InTheOven\agentes_u\agente_leads\main.py", line 8, in extract_title
    title = json.loads(
  File "C:\Program Files\WindowsApps\PythonSoftwareFoundation.Python.3.10_3.10.3056.0_x64__qbz5n2kfra8p0\lib\json\__init__.py", line 346, in loads
    return _default_decoder.decode(s)
  File "C:\Program Files\WindowsApps\PythonSoftwareFoundation.Python.3.10_3.10.3056.0_x64__qbz5n2kfra8p0\lib\json\decoder.py", line 340, in decode
    raise JSONDecodeError("Extra data", s, end)
json.decoder.JSONDecodeError: Extra data: line 1 column 378516 (char 378515)

During handling of the above exception, another exception occurred:

Traceback (most recent call last):
  File "C:\Users\marco\Alquimista\0-InTheOven\agentes_u\venv\lib\site-packages\botasaurus\request_decorator.py", line 108, in run_task
    result = func(reqs, data, metadata)
  File "C:\Users\marco\Alquimista\0-InTheOven\agentes_u\agente_leads\main.py", line 35, in scrape_place_info
    title = extract_title(html)
  File "C:\Users\marco\Alquimista\0-InTheOven\agentes_u\agente_leads\main.py", line 8, in extract_title
    title = json.loads(
  File "C:\Program Files\WindowsApps\PythonSoftwareFoundation.Python.3.10_3.10.3056.0_x64__qbz5n2kfra8p0\lib\json\__init__.py", line 346, in loads
    return _default_decoder.decode(s)
  File "C:\Program Files\WindowsApps\PythonSoftwareFoundation.Python.3.10_3.10.3056.0_x64__qbz5n2kfra8p0\lib\json\decoder.py", line 340, in decode
    raise JSONDecodeError("Extra data", s, end)
json.decoder.JSONDecodeError: Extra data: line 1 column 377661 (char 377660)

During handling of the above exception, another exception occurred:

Traceback (most recent call last):
  File "C:\Users\marco\Alquimista\0-InTheOven\agentes_u\venv\lib\site-packages\botasaurus\request_decorator.py", line 108, in run_task
    result = func(reqs, data, metadata)
  File "C:\Users\marco\Alquimista\0-InTheOven\agentes_u\agente_leads\main.py", line 35, in scrape_place_info
    title = extract_title(html)
  File "C:\Users\marco\Alquimista\0-InTheOven\agentes_u\agente_leads\main.py", line 8, in extract_title
    title = json.loads(
  File "C:\Program Files\WindowsApps\PythonSoftwareFoundation.Python.3.10_3.10.3056.0_x64__qbz5n2kfra8p0\lib\json\__init__.py", line 346, in loads
    return _default_decoder.decode(s)
  File "C:\Program Files\WindowsApps\PythonSoftwareFoundation.Python.3.10_3.10.3056.0_x64__qbz5n2kfra8p0\lib\json\decoder.py", line 340, in decode
    raise JSONDecodeError("Extra data", s, end)
json.decoder.JSONDecodeError: Extra data: line 1 column 377681 (char 377680)

During handling of the above exception, another exception occurred:

Traceback (most recent call last):
  File "C:\Users\marco\Alquimista\0-InTheOven\agentes_u\venv\lib\site-packages\botasaurus\request_decorator.py", line 108, in run_task
    result = func(reqs, data, metadata)
  File "C:\Users\marco\Alquimista\0-InTheOven\agentes_u\agente_leads\main.py", line 35, in scrape_place_info
    title = extract_title(html)
  File "C:\Users\marco\Alquimista\0-InTheOven\agentes_u\agente_leads\main.py", line 8, in extract_title
    title = json.loads(
  File "C:\Program Files\WindowsApps\PythonSoftwareFoundation.Python.3.10_3.10.3056.0_x64__qbz5n2kfra8p0\lib\json\__init__.py", line 346, in loads
    return _default_decoder.decode(s)
  File "C:\Program Files\WindowsApps\PythonSoftwareFoundation.Python.3.10_3.10.3056.0_x64__qbz5n2kfra8p0\lib\json\decoder.py", line 340, in decode
    raise JSONDecodeError("Extra data", s, end)
json.decoder.JSONDecodeError: Extra data: line 1 column 378578 (char 378577)

During handling of the above exception, another exception occurred:

Traceback (most recent call last):
  File "C:\Users\marco\Alquimista\0-InTheOven\agentes_u\venv\lib\site-packages\botasaurus\request_decorator.py", line 108, in run_task
    result = func(reqs, data, metadata)
  File "C:\Users\marco\Alquimista\0-InTheOven\agentes_u\agente_leads\main.py", line 35, in scrape_place_info
    title = extract_title(html)
  File "C:\Users\marco\Alquimista\0-InTheOven\agentes_u\agente_leads\main.py", line 8, in extract_title
    title = json.loads(
  File "C:\Program Files\WindowsApps\PythonSoftwareFoundation.Python.3.10_3.10.3056.0_x64__qbz5n2kfra8p0\lib\json\__init__.py", line 346, in loads
    return _default_decoder.decode(s)
  File "C:\Program Files\WindowsApps\PythonSoftwareFoundation.Python.3.10_3.10.3056.0_x64__qbz5n2kfra8p0\lib\json\decoder.py", line 340, in decode
    raise JSONDecodeError("Extra data", s, end)
json.decoder.JSONDecodeError: Extra data: line 1 column 378523 (char 378522)

During handling of the above exception, another exception occurred:

Traceback (most recent call last):
  File "C:\Users\marco\Alquimista\0-InTheOven\agentes_u\venv\lib\site-packages\botasaurus\request_decorator.py", line 108, in run_task
    result = func(reqs, data, metadata)
  File "C:\Users\marco\Alquimista\0-InTheOven\agentes_u\agente_leads\main.py", line 35, in scrape_place_info
    title = extract_title(html)
  File "C:\Users\marco\Alquimista\0-InTheOven\agentes_u\agente_leads\main.py", line 8, in extract_title
    title = json.loads(
  File "C:\Program Files\WindowsApps\PythonSoftwareFoundation.Python.3.10_3.10.3056.0_x64__qbz5n2kfra8p0\lib\json\__init__.py", line 346, in loads
    return _default_decoder.decode(s)
  File "C:\Program Files\WindowsApps\PythonSoftwareFoundation.Python.3.10_3.10.3056.0_x64__qbz5n2kfra8p0\lib\json\decoder.py", line 340, in decode
    raise JSONDecodeError("Extra data", s, end)
json.decoder.JSONDecodeError: Extra data: line 1 column 378785 (char 378784)
